Workbook

Sheet INFO
B2: SkillChamp 2026
B3: OFFICIAL CAMPUS ROUND — JUDGING WORKBOOK
B4: Powered by Connectiya | Bangladesh's #1 Employability Platform
B7: 📋 WORKBOOK GUIDE
B8: This file contains 6 sheets:
B10: 1️⃣ SCOREBOARD | C10: → Auto-calculated final team rankings
B11: 2️⃣ APTITUDE | C11: → Enter individual member MCQ scores
B12: 3️⃣ JUDGE 1 – PRESENTATION | C12: → Judge 1 marks presentation rubric
B13: 4️⃣ JUDGE 2 – PRESENTATION | C13: → Judge 2 marks presentation rubric
B14: 5️⃣ VERBAL & Q&A | C14: → Enter Verbal Comm + Q&A scores
B15: 6️⃣ RUBRIC GUIDE | C15: → Full scoring guide for all judges
B17: 📌 HOW TO USE
B18: Step 1 | C18: Fill team names & university in APTITUDE, JUDGE 1, JUDGE 2, VERBAL sheets
B19: Step 2 | C19: Enter MCQ individual scores in APTITUDE sheet → team average auto-calculates
B20: Step 3 | C20: Each judge fills their own PRESENTATION sheet independently
B21: Step 4 | C21: Enter Verbal and Q&A scores in VERBAL & Q&A sheet
B22: Step 5 | C22: Enter Connectiya Courses (5) and Profile (5) directly in SCOREBOARD
B23: Step 6 | C23: SCOREBOARD auto-calculates TOTAL /100 and RANK for every team
B25: ⚠️ RULES
B26: Do not edit yellow formula cells in SCOREBOARD
B27: Scores outside allowed range will be highlighted in red
B28: Judges must NOT see each other's sheets during scoring
B30: 📍 TOTAL MARKS BREAKDOWN
B31: Segment 1 – Aptitude Test | C31: 35 marks (avg of 3 members)
B32: Segment 2 – Problem-Solving Presentation | C32: 30 marks (avg of 2 judges)
B33: Segment 3 – Verbal Communication | C33: 20 marks
B34: Segment 4 – Judges Q&A | C34: 05 marks
B35: Connectiya Courses Completion | C35: 05 marks
B36: Complete Connectiya Profile | C36: 05 marks
B37: TOTAL | C37: 100 marks

Sheet SCOREBOARD
A1: SkillChamp 2026 | Campus Round — Final Scoreboard
A2: Powered by Connectiya · Scores auto-calculate from all judge sheets · Do NOT manually edit yellow cells
A3: # | B3: Team Name | C3: University | D3: Member 1 | E3: Member 2 | F3: Member 3 | G3: Aptitude /35 | H3: Presentation /30 | I3: Verbal /20 | J3: Q&A /5 | K3: Courses /5 | L3: Profile /5 | M3: TOTAL /100 | N3: Rank
A4: 1 | G4: =IFERROR(APTITUDE!G4,0) -> 0 | H4: =IFERROR(AVERAGE('JUDGE 1 - PRES'!J4,'JUDGE 2 - PRES'!J4),0) -> 0 | I4: =IFERROR('VERBAL & Q&A'!G4,0) -> Confidence & Delivery /5 | J4: =IFERROR('VERBAL & Q&A'!K4,0) -> Q&A Confidence /1 | M4: =SUM(G4:L4) -> 0 | N4: =IF(M4=0,"—",RANK(M4,M4:M23,0)) -> —
A5: 2 | G5: =IFERROR(APTITUDE!G5,0) -> 0 | H5: =IFERROR(AVERAGE('JUDGE 1 - PRES'!J5,'JUDGE 2 - PRES'!J5),0) -> 0 | I5: =IFERROR('VERBAL & Q&A'!G5,0) -> 0 | J5: =IFERROR('VERBAL & Q&A'!K5,0) -> 0 | M5: =SUM(G5:L5) -> 0 | N5: =IF(M5=0,"—",RANK(M5,M4:M23,0)) -> —
A6: 3 | G6: =IFERROR(APTITUDE!G6,0) -> 0 | H6: =IFERROR(AVERAGE('JUDGE 1 - PRES'!J6,'JUDGE 2 - PRES'!J6),0) -> 0 | I6: =IFERROR('VERBAL & Q&A'!G6,0) -> 0 | J6: =IFERROR('VERBAL & Q&A'!K6,0) -> 0 | M6: =SUM(G6:L6) -> 0 | N6: =IF(M6=0,"—",RANK(M6,M4:M23,0)) -> —
A7: 4 | G7: =IFERROR(APTITUDE!G7,0) -> 0 | H7: =IFERROR(AVERAGE('JUDGE 1 - PRES'!J7,'JUDGE 2 - PRES'!J7),0) -> 0 | I7: =IFERROR('VERBAL & Q&A'!G7,0) -> 0 | J7: =IFERROR('VERBAL & Q&A'!K7,0) -> 0 | M7: =SUM(G7:L7) -> 0 | N7: =IF(M7=0,"—",RANK(M7,M4:M23,0)) -> —
A8: 5 | G8: =IFERROR(APTITUDE!G8,0) -> 0 | H8: =IFERROR(AVERAGE('JUDGE 1 - PRES'!J8,'JUDGE 2 - PRES'!J8),0) -> 0 | I8: =IFERROR('VERBAL & Q&A'!G8,0) -> 0 | J8: =IFERROR('VERBAL & Q&A'!K8,0) -> 0 | M8: =SUM(G8:L8) -> 0 | N8: =IF(M8=0,"—",RANK(M8,M4:M23,0)) -> —
A9: 6 | G9: =IFERROR(APTITUDE!G9,0) -> 0 | H9: =IFERROR(AVERAGE('JUDGE 1 - PRES'!J9,'JUDGE 2 - PRES'!J9),0) -> 0 | I9: =IFERROR('VERBAL & Q&A'!G9,0) -> 0 | J9: =IFERROR('VERBAL & Q&A'!K9,0) -> 0 | M9: =SUM(G9:L9) -> 0 | N9: =IF(M9=0,"—",RANK(M9,M4:M23,0)) -> —
A10: 7 | G10: =IFERROR(APTITUDE!G10,0) -> 0 | H10: =IFERROR(AVERAGE('JUDGE 1 - PRES'!J10,'JUDGE 2 - PRES'!J10),0) -> 0 | I10: =IFERROR('VERBAL & Q&A'!G10,0) -> 0 | J10: =IFERROR('VERBAL & Q&A'!K10,0) -> 0 | M10: =SUM(G10:L10) -> 0 | N10: =IF(M10=0,"—",RANK(M10,M4:M23,0)) -> —
A11: 8 | G11: =IFERROR(APTITUDE!G11,0) -> 0 | H11: =IFERROR(AVERAGE('JUDGE 1 - PRES'!J11,'JUDGE 2 - PRES'!J11),0) -> 0 | I11: =IFERROR('VERBAL & Q&A'!G11,0) -> 0 | J11: =IFERROR('VERBAL & Q&A'!K11,0) -> 0 | M11: =SUM(G11:L11) -> 0 | N11: =IF(M11=0,"—",RANK(M11,M4:M23,0)) -> —
A12: 9 | G12: =IFERROR(APTITUDE!G12,0) -> 0 | H12: =IFERROR(AVERAGE('JUDGE 1 - PRES'!J12,'JUDGE 2 - PRES'!J12),0) -> 0 | I12: =IFERROR('VERBAL & Q&A'!G12,0) -> 0 | J12: =IFERROR('VERBAL & Q&A'!K12,0) -> 0 | M12: =SUM(G12:L12) -> 0 | N12: =IF(M12=0,"—",RANK(M12,M4:M23,0)) -> —
A13: 10 | G13: =IFERROR(APTITUDE!G13,0) -> 0 | H13: =IFERROR(AVERAGE('JUDGE 1 - PRES'!J13,'JUDGE 2 - PRES'!J13),0) -> 0 | I13: =IFERROR('VERBAL & Q&A'!G13,0) -> 0 | J13: =IFERROR('VERBAL & Q&A'!K13,0) -> 0 | M13: =SUM(G13:L13) -> 0 | N13: =IF(M13=0,"—",RANK(M13,M4:M23,0)) -> —
A14: 11 | G14: =IFERROR(APTITUDE!G14,0) -> 0 | H14: =IFERROR(AVERAGE('JUDGE 1 - PRES'!J14,'JUDGE 2 - PRES'!J14),0) -> 0 | I14: =IFERROR('VERBAL & Q&A'!G14,0) -> 0 | J14: =IFERROR('VERBAL & Q&A'!K14,0) -> 0 | M14: =SUM(G14:L14) -> 0 | N14: =IF(M14=0,"—",RANK(M14,M4:M23,0)) -> —
A15: 12 | G15: =IFERROR(APTITUDE!G15,0) -> 0 | H15: =IFERROR(AVERAGE('JUDGE 1 - PRES'!J15,'JUDGE 2 - PRES'!J15),0) -> 0 | I15: =IFERROR('VERBAL & Q&A'!G15,0) -> 0 | J15: =IFERROR('VERBAL & Q&A'!K15,0) -> 0 | M15: =SUM(G15:L15) -> 0 | N15: =IF(M15=0,"—",RANK(M15,M4:M23,0)) -> —
A16: 13 | G16: =IFERROR(APTITUDE!G16,0) -> 0 | H16: =IFERROR(AVERAGE('JUDGE 1 - PRES'!J16,'JUDGE 2 - PRES'!J16),0) -> 0 | I16: =IFERROR('VERBAL & Q&A'!G16,0) -> 0 | J16: =IFERROR('VERBAL & Q&A'!K16,0) -> 0 | M16: =SUM(G16:L16) -> 0 | N16: =IF(M16=0,"—",RANK(M16,M4:M23,0)) -> —
A17: 14 | G17: =IFERROR(APTITUDE!G17,0) -> 0 | H17: =IFERROR(AVERAGE('JUDGE 1 - PRES'!J17,'JUDGE 2 - PRES'!J17),0) -> 0 | I17: =IFERROR('VERBAL & Q&A'!G17,0) -> 0 | J17: =IFERROR('VERBAL & Q&A'!K17,0) -> 0 | M17: =SUM(G17:L17) -> 0 | N17: =IF(M17=0,"—",RANK(M17,M4:M23,0)) -> —
A18: 15 | G18: =IFERROR(APTITUDE!G18,0) -> 0 | H18: =IFERROR(AVERAGE('JUDGE 1 - PRES'!J18,'JUDGE 2 - PRES'!J18),0) -> 0 | I18: =IFERROR('VERBAL & Q&A'!G18,0) -> 0 | J18: =IFERROR('VERBAL & Q&A'!K18,0) -> 0 | M18: =SUM(G18:L18) -> 0 | N18: =IF(M18=0,"—",RANK(M18,M4:M23,0)) -> —
A19: 16 | G19: =IFERROR(APTITUDE!G19,0) -> 0 | H19: =IFERROR(AVERAGE('JUDGE 1 - PRES'!J19,'JUDGE 2 - PRES'!J19),0) -> 0 | I19: =IFERROR('VERBAL & Q&A'!G19,0) -> 0 | J19: =IFERROR('VERBAL & Q&A'!K19,0) -> 0 | M19: =SUM(G19:L19) -> 0 | N19: =IF(M19=0,"—",RANK(M19,M4:M23,0)) -> —
A20: 17 | G20: =IFERROR(APTITUDE!G20,0) -> 0 | H20: =IFERROR(AVERAGE('JUDGE 1 - PRES'!J20,'JUDGE 2 - PRES'!J20),0) -> 0 | I20: =IFERROR('VERBAL & Q&A'!G20,0) -> 0 | J20: =IFERROR('VERBAL & Q&A'!K20,0) -> 0 | M20: =SUM(G20:L20) -> 0 | N20: =IF(M20=0,"—",RANK(M20,M4:M23,0)) -> —
A21: 18 | G21: =IFERROR(APTITUDE!G21,0) -> 0 | H21: =IFERROR(AVERAGE('JUDGE 1 - PRES'!J21,'JUDGE 2 - PRES'!J21),0) -> 0 | I21: =IFERROR('VERBAL & Q&A'!G21,0) -> 0 | J21: =IFERROR('VERBAL & Q&A'!K21,0) -> 0 | M21: =SUM(G21:L21) -> 0 | N21: =IF(M21=0,"—",RANK(M21,M4:M23,0)) -> —
A22: 19 | G22: =IFERROR(APTITUDE!G22,0) -> 0 | H22: =IFERROR(AVERAGE('JUDGE 1 - PRES'!J22,'JUDGE 2 - PRES'!J22),0) -> 0 | I22: =IFERROR('VERBAL & Q&A'!G22,0) -> 0 | J22: =IFERROR('VERBAL & Q&A'!K22,0) -> 0 | M22: =SUM(G22:L22) -> 0 | N22: =IF(M22=0,"—",RANK(M22,M4:M23,0)) -> —
A23: 20 | G23: =IFERROR(APTITUDE!G23,0) -> 0 | H23: =IFERROR(AVERAGE('JUDGE 1 - PRES'!J23,'JUDGE 2 - PRES'!J23),0) -> 0 | I23: =IFERROR('VERBAL & Q&A'!G23,0) -> 0 | J23: =IFERROR('VERBAL & Q&A'!K23,0) -> 0 | M23: =SUM(G23:L23) -> 0 | N23: =IF(M23=0,"—",RANK(M23,M4:M23,0)) -> —
A26: LEGEND: 🟡 Yellow cells = auto-calculated (do not edit) 🟢 Green cells = enter manually 🔴 Red = Total 🔵 Blue = Rank

Sheet APTITUDE
A1: SkillChamp 2026 | Segment 1 — Aptitude Test Score Entry
A2: Each member takes the 35-question MCQ test individually (30 min). Team Score = Average of all 3 members.
A3: # | B3: Team Name | C3: University | D3: Member 1 Score /35 | E3: Member 2 Score /35 | F3: Member 3 Score /35 | G3: Team Avg /35
A4: 1 | G4: =IFERROR(AVERAGE(D4:F4),0) -> 0
A5: 2 | G5: =IFERROR(AVERAGE(D5:F5),0) -> 0
A6: 3 | G6: =IFERROR(AVERAGE(D6:F6),0) -> 0
A7: 4 | G7: =IFERROR(AVERAGE(D7:F7),0) -> 0
A8: 5 | G8: =IFERROR(AVERAGE(D8:F8),0) -> 0
A9: 6 | G9: =IFERROR(AVERAGE(D9:F9),0) -> 0
A10: 7 | G10: =IFERROR(AVERAGE(D10:F10),0) -> 0
A11: 8 | G11: =IFERROR(AVERAGE(D11:F11),0) -> 0
A12: 9 | G12: =IFERROR(AVERAGE(D12:F12),0) -> 0
A13: 10 | G13: =IFERROR(AVERAGE(D13:F13),0) -> 0
A14: 11 | G14: =IFERROR(AVERAGE(D14:F14),0) -> 0
A15: 12 | G15: =IFERROR(AVERAGE(D15:F15),0) -> 0
... A23: 20 | G23: =IFERROR(AVERAGE(D23:F23),0) -> 0

Sheet JUDGE 1 - PRES
A1: SkillChamp 2026 | Segment 2 — Problem-Solving Presentation | JUDGE 1 SCORING SHEET
A2: Judge 1: Score each criterion out of 5. Teams present their SDG-based problem solution (5 min). All members must participate. Maximum: 30 marks.
E3: SCORING CRITERIA (each /5 marks)
A4: # | B4: Team Name | C4: University | D4: SDG Problem Topic (in brief) | E4: Problem Selection & SDG Alignment /5 | F4: Solution Quality & Innovation /5 | G4: Leadership & Teamwork /5 | H4: Emotional Intelligence & Empathy /5 | I4: Feasibility & Sustainability /5 | J4: Presentation & Delivery /5 | K4: TOTAL /30 | L4: Comments & Notes | M4: Recommend Advance?
A5: 1 | K5: =IFERROR(SUM(E5:J5),0) -> 0
A6: 2 | K6: =IFERROR(SUM(E6:J6),0) -> 0
A7: 3 | K7: =IFERROR(SUM(E7:J7),0) -> 0
A8: 4 | K8: =IFERROR(SUM(E8:J8),0) -> 0
A9: 5 | K9: =IFERROR(SUM(E9:J9),0) -> 0
A10: 6 | K10: =IFERROR(SUM(E10:J10),0) -> 0
A11: 7 | K11: =IFERROR(SUM(E11:J11),0) -> 0
A12: 8 | K12: =IFERROR(SUM(E12:J12),0) -> 0
A13: 9 | K13: =IFERROR(SUM(E13:J13),0) -> 0
A14: 10 | K14: =IFERROR(SUM(E14:J14),0) -> 0
A15: 11 | K15: =IFERROR(SUM(E15:J15),0) -> 0
A16: 12 | K16: =IFERROR(SUM(E16:J16),0) -> 0
... A24: 20 | K24: =IFERROR(SUM(E24:J24),0) -> 0
A26: QUICK RUBRIC: 5 = Excellent | 4 = Good | 3 = Average | 2 = Below Average | 1 = Poor | 0 = Not Attempted ⟶ See RUBRIC GUIDE sheet for full scoring descriptors

Sheet JUDGE 2 - PRES
A1: SkillChamp 2026 | Segment 2 — Problem-Solving Presentation | JUDGE 2 SCORING SHEET
A2: Judge 2: Score each criterion out of 5. Teams present their SDG-based problem solution (5 min). All members must participate. Maximum: 30 marks.
E3: SCORING CRITERIA (each /5 marks)
A4: # | B4: Team Name | C4: University | D4: SDG Problem Topic (in brief) | E4: Problem Selection & SDG Alignment /5 | F4: Solution Quality & Innovation /5 | G4: Leadership & Teamwork /5 | H4: Emotional Intelligence & Empathy /5 | I4: Feasibility & Sustainability /5 | J4: Presentation & Delivery /5 | K4: TOTAL /30 | L4: Comments & Notes | M4: Recommend Advance?
A5: 1 | K5: =IFERROR(SUM(E5:J5),0) -> 0
A6: 2 | K6: =IFERROR(SUM(E6:J6),0) -> 0
A7: 3 | K7: =IFERROR(SUM(E7:J7),0) -> 0
A8: 4 | K8: =IFERROR(SUM(E8:J8),0) -> 0
A9: 5 | K9: =IFERROR(SUM(E9:J9),0) -> 0
A10: 6 | K10: =IFERROR(SUM(E10:J10),0) -> 0
A11: 7 | K11: =IFERROR(SUM(E11:J11),0) -> 0
A12: 8 | K12: =IFERROR(SUM(E12:J12),0) -> 0
A13: 9 | K13: =IFERROR(SUM(E13:J13),0) -> 0
A14: 10 | K14: =IFERROR(SUM(E14:J14),0) -> 0
A15: 11 | K15: =IFERROR(SUM(E15:J15),0) -> 0
A16: 12 | K16: =IFERROR(SUM(E16:J16),0) -> 0
... A24: 20 | K24: =IFERROR(SUM(E24:J24),0) -> 0
A26: QUICK RUBRIC: 5 = Excellent | 4 = Good | 3 = Average | 2 = Below Average | 1 = Poor | 0 = Not Attempted ⟶ See RUBRIC GUIDE sheet for full scoring descriptors

Sheet VERBAL & Q&A
A1: SkillChamp 2026 | Segment 3 — Verbal Communication & Segment 4 — Judges Q&A
A2: Verbal (20 marks): Topic draw → 2 min prep → 2–3 min speak. Q&A (5 marks): 2–3 questions per team. Total = 25 marks.
D3: VERBAL COMMUNICATION (Segment 3) | H3: JUDGES Q&A (Segment 4)
A4: # | B4: Team Name | C4: University | D4: Fluency /5 | E4: Clarity /5 | F4: Structure Intro-Body -Conclusion /5 | G4: Confidence & Delivery /5 | H4: Verbal TOTAL /20 | I4: Presence of Mind /2 | J4: Answer Relevance /2 | K4: Q&A Confidence /1 | L4: Q&A TOTAL /5
A5: 1 | H5: =IFERROR(SUM(D5:G5),0) -> 0 | L5: =IFERROR(SUM(I5:K5),0) -> 0
A6: 2 | H6: =IFERROR(SUM(D6:G6),0) -> 0 | L6: =IFERROR(SUM(I6:K6),0) -> 0
A7: 3 | H7: =IFERROR(SUM(D7:G7),0) -> 0 | L7: =IFERROR(SUM(I7:K7),0) -> 0
A8: 4 | H8: =IFERROR(SUM(D8:G8),0) -> 0 | L8: =IFERROR(SUM(I8:K8),0) -> 0
A9: 5 | H9: =IFERROR(SUM(D9:G9),0) -> 0 | L9: =IFERROR(SUM(I9:K9),0) -> 0
A10: 6 | H10: =IFERROR(SUM(D10:G10),0) -> 0 | L10: =IFERROR(SUM(I10:K10),0) -> 0
A11: 7 | H11: =IFERROR(SUM(D11:G11),0) -> 0 | L11: =IFERROR(SUM(I11:K11),0) -> 0
A12: 8 | H12: =IFERROR(SUM(D12:G12),0) -> 0 | L12: =IFERROR(SUM(I12:K12),0) -> 0
A13: 9 | H13: =IFERROR(SUM(D13:G13),0) -> 0 | L13: =IFERROR(SUM(I13:K13),0) -> 0
A14: 10 | H14: =IFERROR(SUM(D14:G14),0) -> 0 | L14: =IFERROR(SUM(I14:K14),0) -> 0
A15: 11 | H15: =IFERROR(SUM(D15:G15),0) -> 0 | L15: =IFERROR(SUM(I15:K15),0) -> 0
A16: 12 | H16: =IFERROR(SUM(D16:G16),0) -> 0 | L16: =IFERROR(SUM(I16:K16),0) -> 0
... A24: 20 | H24: =IFERROR(SUM(D24:G24),0) -> 0 | L24: =IFERROR(SUM(I24:K24),0) -> 0

Sheet RUBRIC GUIDE
B1: SkillChamp 2026 | Complete Judging Rubric — All Segments
B3: SEGMENT 2 — PROBLEM-SOLVING PRESENTATION (Total: 30 Marks)
B4: Criteria | C4: Score | D4: Descriptor
B5: Problem Selection & SDG Alignment (5 marks) | C5: 5 | D5: Problem is critically important, clearly mapped to a specific SDG, affects large number of real people, and is well-researched.
C6: 4 | D6: Problem is relevant and SDG-linked, mapping is mostly clear with minor gaps.
C7: 3 | D7: Problem is real but SDG connection is weak, vague, or explained poorly.
C8: 2 | D8: Problem is unclear or barely related to any SDG or social issue.
C9: 1 | D9: No SDG relevance; problem is trivial, copied, or not explained.
B10: Solution Quality & Innovation (5 marks) | C10: 5 | D10: Solution is innovative, directly addresses root cause, practical, and goes beyond existing options.
C11: 4 | D11: Solution is good and relevant, but partially addresses the root cause.
C12: 3 | D12: Solution is generic, lacks innovation but is somewhat applicable.
C13: 2 | D13: Solution is unclear, impractical, or doesn't address the problem well.
C14: 1 | D14: No clear or practical solution presented.
B15: Leadership & Teamwork (5 marks) | C15: 5 | D15: All 3 members contributed equally, clear role division, strong team coordination throughout.
C16: 4 | D16: Most members participated actively, good overall coordination.
C17: 3 | D17: Some members dominated; participation was noticeably uneven.
C18: 2 | D18: Only 1–2 members spoke; poor teamwork evident.
C19: 1 | D19: No evidence of collaborative teamwork.
B20: Emotional Intelligence & Empathy (5 marks) | C20: 5 | D20: Deep human understanding; clearly addressed emotional and social impact on affected people.
C21: 4 | D21: Good empathy shown; human angle covered meaningfully.
C22: 3 | D22: Surface-level acknowledgment of human impact.
C23: 2 | D23: Minimal consideration shown for people affected by the problem.
C24: 1 | D24: No empathy or human angle present in the presentation.
B25: Feasibility & Sustainability (5 marks) | C25: 5 | D25: Fully implementable, cost-effective, scalable, and long-term viable with realistic plan.
C26: 4 | D26: Mostly feasible with minor gaps in sustainability planning.
C27: 3 | D27: Partially feasible; significant implementation challenges remain unaddressed.
C28: 2 | D28: Idea is interesting but not practically implementable as presented.
C29: 1 | D29: No feasibility or sustainability considered.
B30: Presentation & Delivery (5 marks) | C30: 5 | D30: Confident, well-structured (Intro-Body-Conclusion), engaging delivery that keeps judges' attention.
C31: 4 | D31: Good structure with minor delivery issues; mostly clear.
C32: 3 | D32: Average delivery; structure incomplete or hard to follow at times.
C33: 2 | D33: Weak delivery; disorganised; difficult to understand.
C34: 1 | D34: Very poor presentation; no structure; unable to communicate ideas.
B36: SEGMENT 3 — VERBAL COMMUNICATION (Total: 20 Marks)
B37: Criteria | C37: Score | D37: Descriptor
B38: Fluency (5 marks) | C38: 5 | D38: Speaks smoothly with natural flow and minimal hesitation. Accent is NOT judged.
C39: 4 | D39: Mostly fluent with slight pauses or repetitions.
C40: 3 | D40: Some hesitation but communication is understandable.
C41: 2 | D41: Frequent stops; broken delivery affects meaning.
C42: 1 | D42: Very hesitant; mostly incoherent delivery.
...
